<mujoco model="dreamsat_scene">
  <!-- DreamSat HIL Testbed Scene -->
  <compiler meshdir="meshes" angle="radian"/>

  <size nkey="2"/>

  <visual>
    <global offwidth="2560" offheight="1440"/>
    <headlight ambient="0.01 0.01 0.02" diffuse="0.1 0.1 0.1" specular="0 0 0"/>
    <map fogstart="5" fogend="20" zfar="1000" haze="0.05"/>
  </visual>

  <statistic extent="2" center="0 0 0.5"/>

  <default>
    <default class="arm_xarm7_left_main">
      <default class="arm_xarm7_left_xarm7">
        <joint range="-6.28319 6.28319" armature="0.1" frictionloss="1"/>
        <geom type="mesh" material="white"/>
        <site size="0.001 0.005 0.005" group="4" rgba="1 0 0 1"/>
        <general ctrlrange="-6.28319 6.28319" biastype="affine"/>
        <default class="arm_xarm7_left_size1">
          <joint damping="10"/>
          <general forcerange="-50 50" gainprm="1500" biasprm="0 -1500 -150"/>
        </default>
        <default class="arm_xarm7_left_size2">
          <joint damping="5"/>
          <general forcerange="-30 30" gainprm="1000" biasprm="0 -1000 -100"/>
        </default>
        <default class="arm_xarm7_left_size3">
          <joint damping="2"/>
          <general forcerange="-20 20" gainprm="800" biasprm="0 -800 -80"/>
        </default>
      </default>
    </default>
    <default class="spacecraft_target_left_main"/>
    <default class="arm_xarm7_right_main">
      <default class="arm_xarm7_right_xarm7">
        <joint range="-6.28319 6.28319" armature="0.1" frictionloss="1"/>
        <geom type="mesh" material="white"/>
        <site size="0.001 0.005 0.005" group="4" rgba="1 0 0 1"/>
        <general ctrlrange="-6.28319 6.28319" biastype="affine"/>
        <default class="arm_xarm7_right_size1">
          <joint damping="10"/>
          <general forcerange="-50 50" gainprm="1500" biasprm="0 -1500 -150"/>
        </default>
        <default class="arm_xarm7_right_size2">
          <joint damping="5"/>
          <general forcerange="-30 30" gainprm="1000" biasprm="0 -1000 -100"/>
        </default>
        <default class="arm_xarm7_right_size3">
          <joint damping="2"/>
          <general forcerange="-20 20" gainprm="800" biasprm="0 -800 -80"/>
        </default>
      </default>
    </default>
    <default class="spacecraft_chaser_right_main"/>
  </default>

  <asset>
    <texture type="skybox" colorspace="auto" name="space" builtin="flat" rgb1="0.002 0.002 0.005" rgb2="0 0 0" width="512" height="3072"/>
    <material name="space_mat" texture="space"/>
    <material name="earth_mat" specular="0.1" shininess="0.1" rgba="0.1 0.3 0.7 1"/>
    <material name="atmosphere_mat" rgba="0.4 0.6 1 0.1"/>
    <material name="black_void" specular="0" shininess="0" rgba="0 0 0 1"/>
    <material name="arm_xarm7_left_white"/>
    <material name="arm_xarm7_left_gray" rgba="0.753 0.753 0.753 1"/>
    <material name="spacecraft_target_left_target_body" rgba="0.8 0.6 0.2 1"/>
    <material name="spacecraft_target_left_target_solar" rgba="0.2 0.2 0.4 1"/>
    <material name="spacecraft_target_left_docking_port" rgba="0.5 0.5 0.5 1"/>
    <material name="spacecraft_target_left_marker" rgba="1 0 0 1"/>
    <material name="arm_xarm7_right_white"/>
    <material name="arm_xarm7_right_gray" rgba="0.753 0.753 0.753 1"/>
    <material name="spacecraft_chaser_right_chaser_body" rgba="0.2 0.2 0.8 1"/>
    <material name="spacecraft_chaser_right_solar_panel" rgba="0.1 0.1 0.3 1"/>
    <material name="spacecraft_chaser_right_camera_lens" rgba="0.1 0.1 0.1 1"/>
    <mesh name="arm_xarm7_left_link_base" file="arm_xarm7_left_link_base.stl"/>
    <mesh name="arm_xarm7_left_link1" file="arm_xarm7_left_link1.stl"/>
    <mesh name="arm_xarm7_left_link2" file="arm_xarm7_left_link2.stl"/>
    <mesh name="arm_xarm7_left_link3" file="arm_xarm7_left_link3.stl"/>
    <mesh name="arm_xarm7_left_link4" file="arm_xarm7_left_link4.stl"/>
    <mesh name="arm_xarm7_left_link5" file="arm_xarm7_left_link5.stl"/>
    <mesh name="arm_xarm7_left_link6" file="arm_xarm7_left_link6.stl"/>
    <mesh name="arm_xarm7_left_link7" file="arm_xarm7_left_link7.stl"/>
    <mesh name="arm_xarm7_left_end_tool" file="arm_xarm7_left_end_tool.stl"/>
    <mesh name="arm_xarm7_right_link_base" file="arm_xarm7_right_link_base.stl"/>
    <mesh name="arm_xarm7_right_link1" file="arm_xarm7_right_link1.stl"/>
    <mesh name="arm_xarm7_right_link2" file="arm_xarm7_right_link2.stl"/>
    <mesh name="arm_xarm7_right_link3" file="arm_xarm7_right_link3.stl"/>
    <mesh name="arm_xarm7_right_link4" file="arm_xarm7_right_link4.stl"/>
    <mesh name="arm_xarm7_right_link5" file="arm_xarm7_right_link5.stl"/>
    <mesh name="arm_xarm7_right_link6" file="arm_xarm7_right_link6.stl"/>
    <mesh name="arm_xarm7_right_link7" file="arm_xarm7_right_link7.stl"/>
    <mesh name="arm_xarm7_right_end_tool" file="arm_xarm7_right_end_tool.stl"/>
  </asset>

  <worldbody>
    <geom name="floor" size="100 100 0.1" pos="0 0 -1" type="plane" material="black_void"/>
    <camera name="overhead" pos="0 -2 2.5" quat="0.866029 0.499994 0 0" fovy="60"/>
    <camera name="side_view" pos="2 0 1" quat="0.592904 0.385312 0.385312 0.592904" fovy="50"/>
    <light name="sun" pos="5 2 5" dir="-0.680414 -0.272166 -0.680414" type="directional" diffuse="1 0.95 0.9" specular="0.8 0.8 0.8"/>
    <light name="fill_top" pos="0 0 3" dir="0 0 -1" diffuse="0.2 0.2 0.3"/>
    <light name="fill_front" pos="2 0 1" dir="-0.980581 0 -0.196116" diffuse="0.15 0.15 0.2"/>
    <body name="earth" pos="0 40 -15">
      <geom name="earth_sphere" size="20" contype="0" conaffinity="0" material="earth_mat"/>
      <geom name="atmosphere_sphere" size="20.5" contype="0" conaffinity="0" material="atmosphere_mat"/>
    </body>
    <body name="target_mount" pos="-0.5 0 0">
      <site name="target_attachment_site" pos="0 0 0" size="0.02"/>
      <body name="arm_xarm7_left_link_base" childclass="arm_xarm7_left_xarm7">
        <inertial pos="-0.021131 -0.0016302 0.056488" quat="0.696843 0.20176 0.10388 0.680376" mass="0.88556" diaginertia="0.00382023 0.00335282 0.00167725"/>
        <geom material="arm_xarm7_left_white" mesh="arm_xarm7_left_link_base"/>
        <body name="arm_xarm7_left_link1" pos="0 0 0.267">
          <inertial pos="-0.0002 0.02905 -0.01233" quat="0.978953 -0.202769 -0.00441617 -0.0227264" mass="2.382" diaginertia="0.00569127 0.00533384 0.00293865"/>
          <joint name="arm_xarm7_left_joint1" class="arm_xarm7_left_size1" pos="0 0 0" axis="0 0 1"/>
          <geom material="arm_xarm7_left_white" mesh="arm_xarm7_left_link1"/>
          <body name="arm_xarm7_left_link2" quat="0.707107 -0.707107 0 0">
            <inertial pos="0.00022 -0.12856 0.01735" quat="0.50198 0.86483 -0.00778841 0.00483285" mass="1.869" diaginertia="0.00959898 0.00937717 0.00201315"/>
            <joint name="arm_xarm7_left_joint2" class="arm_xarm7_left_size1" pos="0 0 0" axis="0 0 1" range="-2.059 2.0944"/>
            <geom material="arm_xarm7_left_white" mesh="arm_xarm7_left_link2"/>
            <body name="arm_xarm7_left_link3" pos="0 -0.293 0" quat="0.707107 0.707107 0 0">
              <inertial pos="0.0466 -0.02463 -0.00768" quat="0.913819 0.289775 0.281481 -0.0416455" mass="1.6383" diaginertia="0.00351721 0.00294089 0.00195868"/>
              <joint name="arm_xarm7_left_joint3" class="arm_xarm7_left_size2" pos="0 0 0" axis="0 0 1"/>
              <geom material="arm_xarm7_left_white" mesh="arm_xarm7_left_link3"/>
              <body name="arm_xarm7_left_link4" pos="0.0525 0 0" quat="0.707107 0.707107 0 0">
                <inertial pos="0.07047 -0.11575 0.012" quat="0.422108 0.852026 -0.126025 0.282832" mass="1.7269" diaginertia="0.00657137 0.00647948 0.00186763"/>
                <joint name="arm_xarm7_left_joint4" class="arm_xarm7_left_size2" pos="0 0 0" axis="0 0 1" range="-0.19198 3.927"/>
                <geom material="arm_xarm7_left_white" mesh="arm_xarm7_left_link4"/>
                <body name="arm_xarm7_left_link5" pos="0.0775 -0.3425 0" quat="0.707107 0.707107 0 0">
                  <inertial pos="-0.00032 0.01604 -0.026" quat="0.999311 -0.0304457 0.000577067 0.0212082" mass="1.3203" diaginertia="0.00534729 0.00499076 0.0013489"/>
                  <joint name="arm_xarm7_left_joint5" class="arm_xarm7_left_size2" pos="0 0 0" axis="0 0 1"/>
                  <geom material="arm_xarm7_left_white" mesh="arm_xarm7_left_link5"/>
                  <body name="arm_xarm7_left_link6" quat="0.707107 0.707107 0 0">
                    <inertial pos="0.06469 0.03278 0.02141" quat="-0.217672 0.772419 0.16258 0.574069" mass="1.325" diaginertia="0.00245421 0.00221646 0.00107273"/>
                    <joint name="arm_xarm7_left_joint6" class="arm_xarm7_left_size3" pos="0 0 0" axis="0 0 1" range="-1.69297 3.14159"/>
                    <geom material="arm_xarm7_left_white" mesh="arm_xarm7_left_link6"/>
                    <body name="arm_xarm7_left_link7" pos="0.076 0.097 0" quat="0.707107 -0.707107 0 0">
                      <inertial pos="0 -0.00677 -0.01098" quat="0.487612 0.512088 -0.512088 0.487612" mass="0.17" diaginertia="0.000132176 9.3e-05 5.85236e-05"/>
                      <joint name="arm_xarm7_left_joint7" class="arm_xarm7_left_size3" pos="0 0 0" axis="0 0 1"/>
                      <geom material="arm_xarm7_left_gray" mesh="arm_xarm7_left_end_tool"/>
                      <site name="arm_xarm7_left_attachment_site" pos="0 0 0"/>
                      <body name="spacecraft_target_left_target">
                        <geom name="spacecraft_target_left_target_body" size="0.075 0.025 0.025" type="box" mass="0.05" material="spacecraft_target_left_target_body"/>
                        <geom name="spacecraft_target_left_solar_top" size="0.06 0.03 0.02" pos="0 0.06 0" type="box" mass="0.01" material="spacecraft_target_left_target_solar"/>
                        <geom name="spacecraft_target_left_solar_bottom" size="0.06 0.03 0.02" pos="0 -0.06 0" type="box" mass="0.01" material="spacecraft_target_left_target_solar"/>
                        <geom name="spacecraft_target_left_docking_port" size="0.015 0.005" pos="0.08 0 0" quat="0.707107 0 0.707107 0" type="cylinder" mass="0.005" material="spacecraft_target_left_docking_port"/>
                        <geom name="spacecraft_target_left_marker_1" type="sphere" size="0.004" pos="0.075 0.025 0.025" material="spacecraft_target_left_marker"/>
                        <geom name="spacecraft_target_left_marker_2" type="sphere" size="0.004" pos="0.075 -0.025 0.025" material="spacecraft_target_left_marker"/>
                        <geom name="spacecraft_target_left_marker_3" type="sphere" size="0.004" pos="0.075 0.025 -0.025" material="spacecraft_target_left_marker"/>
                        <geom name="spacecraft_target_left_marker_4" type="sphere" size="0.004" pos="0.075 -0.025 -0.025" material="spacecraft_target_left_marker"/>
                        <site name="spacecraft_target_left_target_center" pos="0 0 0"/>
                        <site name="spacecraft_target_left_target_attachment" pos="-0.08 0 0" quat="0.707107 0 -0.707107 0"/>
                      </body>
                    </body>
                  </body>
                </body>
              </body>
            </body>
          </body>
        </body>
      </body>
    </body>
    <body name="chaser_mount" pos="0.5 0 0" quat="1.32679e-06 0 0 1">
      <site name="chaser_attachment_site" pos="0 0 0" size="0.02"/>
      <body name="arm_xarm7_right_link_base" childclass="arm_xarm7_right_xarm7">
        <inertial pos="-0.021131 -0.0016302 0.056488" quat="0.696843 0.20176 0.10388 0.680376" mass="0.88556" diaginertia="0.00382023 0.00335282 0.00167725"/>
        <geom material="arm_xarm7_right_white" mesh="arm_xarm7_right_link_base"/>
        <body name="arm_xarm7_right_link1" pos="0 0 0.267">
          <inertial pos="-0.0002 0.02905 -0.01233" quat="0.978953 -0.202769 -0.00441617 -0.0227264" mass="2.382" diaginertia="0.00569127 0.00533384 0.00293865"/>
          <joint name="arm_xarm7_right_joint1" class="arm_xarm7_right_size1" pos="0 0 0" axis="0 0 1"/>
          <geom material="arm_xarm7_right_white" mesh="arm_xarm7_right_link1"/>
          <body name="arm_xarm7_right_link2" quat="0.707107 -0.707107 0 0">
            <inertial pos="0.00022 -0.12856 0.01735" quat="0.50198 0.86483 -0.00778841 0.00483285" mass="1.869" diaginertia="0.00959898 0.00937717 0.00201315"/>
            <joint name="arm_xarm7_right_joint2" class="arm_xarm7_right_size1" pos="0 0 0" axis="0 0 1" range="-2.059 2.0944"/>
            <geom material="arm_xarm7_right_white" mesh="arm_xarm7_right_link2"/>
            <body name="arm_xarm7_right_link3" pos="0 -0.293 0" quat="0.707107 0.707107 0 0">
              <inertial pos="0.0466 -0.02463 -0.00768" quat="0.913819 0.289775 0.281481 -0.0416455" mass="1.6383" diaginertia="0.00351721 0.00294089 0.00195868"/>
              <joint name="arm_xarm7_right_joint3" class="arm_xarm7_right_size2" pos="0 0 0" axis="0 0 1"/>
              <geom material="arm_xarm7_right_white" mesh="arm_xarm7_right_link3"/>
              <body name="arm_xarm7_right_link4" pos="0.0525 0 0" quat="0.707107 0.707107 0 0">
                <inertial pos="0.07047 -0.11575 0.012" quat="0.422108 0.852026 -0.126025 0.282832" mass="1.7269" diaginertia="0.00657137 0.00647948 0.00186763"/>
                <joint name="arm_xarm7_right_joint4" class="arm_xarm7_right_size2" pos="0 0 0" axis="0 0 1" range="-0.19198 3.927"/>
                <geom material="arm_xarm7_right_white" mesh="arm_xarm7_right_link4"/>
                <body name="arm_xarm7_right_link5" pos="0.0775 -0.3425 0" quat="0.707107 0.707107 0 0">
                  <inertial pos="-0.00032 0.01604 -0.026" quat="0.999311 -0.0304457 0.000577067 0.0212082" mass="1.3203" diaginertia="0.00534729 0.00499076 0.0013489"/>
                  <joint name="arm_xarm7_right_joint5" class="arm_xarm7_right_size2" pos="0 0 0" axis="0 0 1"/>
                  <geom material="arm_xarm7_right_white" mesh="arm_xarm7_right_link5"/>
                  <body name="arm_xarm7_right_link6" quat="0.707107 0.707107 0 0">
                    <inertial pos="0.06469 0.03278 0.02141" quat="-0.217672 0.772419 0.16258 0.574069" mass="1.325" diaginertia="0.00245421 0.00221646 0.00107273"/>
                    <joint name="arm_xarm7_right_joint6" class="arm_xarm7_right_size3" pos="0 0 0" axis="0 0 1" range="-1.69297 3.14159"/>
                    <geom material="arm_xarm7_right_white" mesh="arm_xarm7_right_link6"/>
                    <body name="arm_xarm7_right_link7" pos="0.076 0.097 0" quat="0.707107 -0.707107 0 0">
                      <inertial pos="0 -0.00677 -0.01098" quat="0.487612 0.512088 -0.512088 0.487612" mass="0.17" diaginertia="0.000132176 9.3e-05 5.85236e-05"/>
                      <joint name="arm_xarm7_right_joint7" class="arm_xarm7_right_size3" pos="0 0 0" axis="0 0 1"/>
                      <geom material="arm_xarm7_right_gray" mesh="arm_xarm7_right_end_tool"/>
                      <site name="arm_xarm7_right_attachment_site" pos="0 0 0"/>
                      <body name="spacecraft_chaser_right_chaser">
                        <geom name="spacecraft_chaser_right_chaser_body" size="0.075 0.025 0.025" type="box" mass="0.05" material="spacecraft_chaser_right_chaser_body"/>
                        <geom name="spacecraft_chaser_right_solar_top" size="0.06 0.02 0.02" pos="0 0.05 0" type="box" mass="0.01" material="spacecraft_chaser_right_solar_panel"/>
                        <geom name="spacecraft_chaser_right_solar_bottom" size="0.06 0.02 0.02" pos="0 -0.05 0" type="box" mass="0.01" material="spacecraft_chaser_right_solar_panel"/>
                        <site name="spacecraft_chaser_right_chaser_attachment" pos="0 0 -0.085" quat="0.707107 0 -0.707107 0"/>
                        <camera name="spacecraft_chaser_right_custom_view" pos="0 0 -0.021" quat="-0.00984649 0.703494 0.710564 -0.00994545"/>
                      </body>
                    </body>
                  </body>
                </body>
              </body>
            </body>
          </body>
        </body>
      </body>
    </body>
  </worldbody>

  <actuator>
    <general name="arm_xarm7_left_act1" class="arm_xarm7_left_size1" joint="arm_xarm7_left_joint1"/>
    <general name="arm_xarm7_left_act2" class="arm_xarm7_left_size1" joint="arm_xarm7_left_joint2" ctrlrange="-2.059 2.0944"/>
    <general name="arm_xarm7_left_act3" class="arm_xarm7_left_size2" joint="arm_xarm7_left_joint3"/>
    <general name="arm_xarm7_left_act4" class="arm_xarm7_left_size2" joint="arm_xarm7_left_joint4" ctrlrange="-0.19198 3.927"/>
    <general name="arm_xarm7_left_act5" class="arm_xarm7_left_size2" joint="arm_xarm7_left_joint5"/>
    <general name="arm_xarm7_left_act6" class="arm_xarm7_left_size3" joint="arm_xarm7_left_joint6" ctrlrange="-1.69297 3.14159"/>
    <general name="arm_xarm7_left_act7" class="arm_xarm7_left_size3" joint="arm_xarm7_left_joint7"/>
    <general name="arm_xarm7_right_act1" class="arm_xarm7_right_size1" joint="arm_xarm7_right_joint1"/>
    <general name="arm_xarm7_right_act2" class="arm_xarm7_right_size1" joint="arm_xarm7_right_joint2" ctrlrange="-2.059 2.0944"/>
    <general name="arm_xarm7_right_act3" class="arm_xarm7_right_size2" joint="arm_xarm7_right_joint3"/>
    <general name="arm_xarm7_right_act4" class="arm_xarm7_right_size2" joint="arm_xarm7_right_joint4" ctrlrange="-0.19198 3.927"/>
    <general name="arm_xarm7_right_act5" class="arm_xarm7_right_size2" joint="arm_xarm7_right_joint5"/>
    <general name="arm_xarm7_right_act6" class="arm_xarm7_right_size3" joint="arm_xarm7_right_joint6" ctrlrange="-1.69297 3.14159"/>
    <general name="arm_xarm7_right_act7" class="arm_xarm7_right_size3" joint="arm_xarm7_right_joint7"/>
  </actuator>

  <keyframe>
    <key name="arm_xarm7_left_home" qpos="0.0 -0.4 0.0 0.4 0.0 -0.8 0.0 0 0 0 0 0 0 0" ctrl="0.0 -0.4 0.0 0.4 0.0 -0.8 0.0 0 0 0 0 0 0 0"/>
    <key name="arm_xarm7_right_home" qpos="0 0 0 0 0 0 0 0.0 -0.4 0.0 0.4 0.0 -0.8 0.0" ctrl="0 0 0 0 0 0 0 0.0 -0.4 0.0 0.4 0.0 -0.8 0.0"/>
  </keyframe>
</mujoco>
